"""Config flow for EMT Madrid integration."""

from __future__ import annotations

import logging
from typing import Any

import voluptuous as vol

from homeassistant.config_entries import ConfigFlow, ConfigFlowResult
from homeassistant.const import CONF_PASSWORD, CONF_USERNAME
from homeassistant.core import HomeAssistant
from homeassistant.exceptions import HomeAssistantError

from .const import CONF_STOP_ID, DOMAIN
from .util import async_get_api_emt_instance

_LOGGER = logging.getLogger(__name__)


STEP_USER_DATA_SCHEMA = vol.Schema(
    {
        vol.Required(CONF_STOP_ID): str,
        vol.Required(CONF_USERNAME): str,
        vol.Required(CONF_PASSWORD): str,
    }
)


async def validate_input(hass: HomeAssistant, data: dict[str, Any]) -> dict[str, Any]:
    """Validate the user input allows us to connect."""

    api_emt = await async_get_api_emt_instance(data)
    stop_info = api_emt.get_stop_info()
    if not stop_info:
        raise InvalidAuth

    return {"title": "EMT Madrid"}


class ConfigFlow(ConfigFlow, domain=DOMAIN):
    """Handle a config flow for EMT Madrid."""

    VERSION = 1

    async def async_step_user(
        self, user_input: dict[str, Any] | None = None
    ) -> ConfigFlowResult:
        """Handle the initial step."""
        errors: dict[str, str] = {}
        if user_input is not None:
            try:
                info = await validate_input(self.hass, user_input)
            except CannotConnect:
                errors["base"] = "cannot_connect"
            except InvalidAuth:
                errors["base"] = "invalid_auth"
            except Exception:
                _LOGGER.exception("Unexpected exception")
                errors["base"] = "unknown"
            else:
                return self.async_create_entry(title=info["title"], data=user_input)

        return self.async_show_form(
            step_id="user", data_schema=STEP_USER_DATA_SCHEMA, errors=errors
        )


class CannotConnect(HomeAssistantError):
    """Error to indicate we cannot connect."""


class InvalidAuth(HomeAssistantError):
    """Error to indicate there is invalid auth."""
